Traceback (most recent call last):
  File "/home/natalie/.local/lib/python3.9/site-packages/jupyter_cache/executors/utils.py", line 51, in single_nb_execution
    executenb(
  File "/home/natalie/.local/lib/python3.9/site-packages/nbclient/client.py", line 1204, in execute
    return NotebookClient(nb=nb, resources=resources, km=km, **kwargs).execute()
  File "/home/natalie/.local/lib/python3.9/site-packages/nbclient/util.py", line 84, in wrapped
    return just_run(coro(*args, **kwargs))
  File "/home/natalie/.local/lib/python3.9/site-packages/nbclient/util.py", line 62, in just_run
    return loop.run_until_complete(coro)
  File "/usr/lib/python3.9/asyncio/base_events.py", line 647, in run_until_complete
    return future.result()
  File "/home/natalie/.local/lib/python3.9/site-packages/nbclient/client.py", line 663, in async_execute
    await self.async_execute_cell(
  File "/home/natalie/.local/lib/python3.9/site-packages/nbclient/client.py", line 965, in async_execute_cell
    await self._check_raise_for_error(cell, cell_index, exec_reply)
  File "/home/natalie/.local/lib/python3.9/site-packages/nbclient/client.py", line 862, in _check_raise_for_error
    raise CellExecutionError.from_cell_and_msg(cell, exec_reply_content)
nbclient.exceptions.CellExecutionError: An error occurred while executing the following cell:
------------------
absoluter_pfad = '/home/natalie/Documents/Datenjournalismus in Python/Code/vorlesung/'
filename = 'data.txt'

pfad = absoluter_pfad + filename
with open(pfad, "r") as f:
    test = f.read()
------------------

[0;31m---------------------------------------------------------------------------[0m
[0;31mFileNotFoundError[0m                         Traceback (most recent call last)
Cell [0;32mIn [3], line 5[0m
[1;32m      2[0m filename [38;5;241m=[39m [38;5;124m'[39m[38;5;124mdata.txt[39m[38;5;124m'[39m
[1;32m      4[0m pfad [38;5;241m=[39m absoluter_pfad [38;5;241m+[39m filename
[0;32m----> 5[0m [38;5;28;01mwith[39;00m [38;5;28mopen[39m(pfad, [38;5;124m"[39m[38;5;124mr[39m[38;5;124m"[39m) [38;5;28;01mas[39;00m f:
[1;32m      6[0m     test [38;5;241m=[39m f[38;5;241m.[39mread()

[0;31mFileNotFoundError[0m: [Errno 2] No such file or directory: '/home/natalie/Documents/Datenjournalismus in Python/Code/vorlesung/data.txt'
FileNotFoundError: [Errno 2] No such file or directory: '/home/natalie/Documents/Datenjournalismus in Python/Code/vorlesung/data.txt'

