Traceback (most recent call last):
  File "/home/natalie-widmann/anaconda3/lib/python3.11/site-packages/jupyter_cache/executors/utils.py", line 58, in single_nb_execution
    executenb(
  File "/home/natalie-widmann/anaconda3/lib/python3.11/site-packages/nbclient/client.py", line 1305, in execute
    return NotebookClient(nb=nb, resources=resources, km=km, **kwargs).execute()
           ^^^^^^^^^^^^^^^^^^^^^^^^^^^^^^^^^^^^^^^^^^^^^^^^^^^^^^^^^^^^^^^^^^^^^
  File "/home/natalie-widmann/anaconda3/lib/python3.11/site-packages/jupyter_core/utils/__init__.py", line 173, in wrapped
    return loop.run_until_complete(inner)
           ^^^^^^^^^^^^^^^^^^^^^^^^^^^^^^
  File "/home/natalie-widmann/anaconda3/lib/python3.11/asyncio/base_events.py", line 653, in run_until_complete
    return future.result()
           ^^^^^^^^^^^^^^^
  File "/home/natalie-widmann/anaconda3/lib/python3.11/site-packages/nbclient/client.py", line 705, in async_execute
    await self.async_execute_cell(
  File "/home/natalie-widmann/anaconda3/lib/python3.11/site-packages/nbclient/client.py", line 1058, in async_execute_cell
    await self._check_raise_for_error(cell, cell_index, exec_reply)
  File "/home/natalie-widmann/anaconda3/lib/python3.11/site-packages/nbclient/client.py", line 914, in _check_raise_for_error
    raise CellExecutionError.from_cell_and_msg(cell, exec_reply_content)
nbclient.exceptions.CellExecutionError: An error occurred while executing the following cell:
------------------
absoluter_pfad = '/home/natalie/Documents/Datenjournalismus in Python/Code/vorlesung/'
filename = 'data.txt'

pfad = absoluter_pfad + filename
with open(pfad, "r") as f:
    test = f.read()
------------------


[0;31m---------------------------------------------------------------------------[0m
[0;31mFileNotFoundError[0m                         Traceback (most recent call last)
Cell [0;32mIn[3], line 5[0m
[1;32m      2[0m filename [38;5;241m=[39m [38;5;124m'[39m[38;5;124mdata.txt[39m[38;5;124m'[39m
[1;32m      4[0m pfad [38;5;241m=[39m absoluter_pfad [38;5;241m+[39m filename
[0;32m----> 5[0m [38;5;28;01mwith[39;00m [38;5;28mopen[39m(pfad, [38;5;124m"[39m[38;5;124mr[39m[38;5;124m"[39m) [38;5;28;01mas[39;00m f:
[1;32m      6[0m     test [38;5;241m=[39m f[38;5;241m.[39mread()

File [0;32m~/anaconda3/lib/python3.11/site-packages/IPython/core/interactiveshell.py:310[0m, in [0;36m_modified_open[0;34m(file, *args, **kwargs)[0m
[1;32m    303[0m [38;5;28;01mif[39;00m file [38;5;129;01min[39;00m {[38;5;241m0[39m, [38;5;241m1[39m, [38;5;241m2[39m}:
[1;32m    304[0m     [38;5;28;01mraise[39;00m [38;5;167;01mValueError[39;00m(
[1;32m    305[0m         [38;5;124mf[39m[38;5;124m"[39m[38;5;124mIPython won[39m[38;5;124m'[39m[38;5;124mt let you open fd=[39m[38;5;132;01m{[39;00mfile[38;5;132;01m}[39;00m[38;5;124m by default [39m[38;5;124m"[39m
[1;32m    306[0m         [38;5;124m"[39m[38;5;124mas it is likely to crash IPython. If you know what you are doing, [39m[38;5;124m"[39m
[1;32m    307[0m         [38;5;124m"[39m[38;5;124myou can use builtins[39m[38;5;124m'[39m[38;5;124m open.[39m[38;5;124m"[39m
[1;32m    308[0m     )
[0;32m--> 310[0m [38;5;28;01mreturn[39;00m io_open(file, [38;5;241m*[39margs, [38;5;241m*[39m[38;5;241m*[39mkwargs)

[0;31mFileNotFoundError[0m: [Errno 2] No such file or directory: '/home/natalie/Documents/Datenjournalismus in Python/Code/vorlesung/data.txt'

